Workbook

Sheet Cover (Tổng quan)
C2: TRƯỜNG HỢP KIỂM THỬ | I2: File này là file report cuối cùng của dự án
B4: Project Name | C4: Tên dự án | F4: Creator | G4: Người tạo ghi tên và mã sinh viên
B5: Project Code | C5: Mã dự án WEBBONG2020 | F5: Reviewer/Approver | G5: Người phản biện và người phê duyệt
B6: Document Code | C6: Mã dự án + tên | F6: Issue Date | G6: Ngày tạo
F7: Version | G7: Phiên bản v1.0
B10: Record of change | C10: Ghi lại các thay đổi
B11: Effective Date | C11: Version | D11: Change Item | E11: *A,D,M | F11: Change description | G11: Reference
B12: =NOW() -> 45827.59 | C12: 1.0 | H12: Các version thực hiện test khác nhau
B13: Ngày hiệu lực | C13: Phiên bản | D13: Thay đổi hạng mục | E13: Add: Thêm | F13: Mô tả thay đổi gì trong phiên bản | G13: Tài liệu tham khảo là tài liệu nào | H13: Dạng kiểu file Test case
E14: Delete:Xóa
E15: Modify: Sửa
B17: Group: | C17: 5
D18: MEMBER
B19: STT | C19: Tên thành viên | F19: Nhiệm vụ
B20: 1
B21: 2
B22: 3
B23: 4
B24: 5
B25: 6

Sheet Test case List (DS Test Case)
D1: TEST CASE LIST
B3: Project Name | D3: 0
B4: Project Code | D4: 0
B5: Test Environment Setup Description | D5: Môi trường thiết lập để có thể test là gì
B8: No(STT) | C8: Function Name(Tên chức năng) | D8: Sheet Name(Tên Sheet trong excel) | E8: Description(Mô tả) | F8: Pre-Condition(Điều kiện trước khi test)
B9: 1
B10: 2
B11: 3
B12: 4
B13: 5
B14: 6
B15: 7

Sheet FUNCTION
C1: FUNCTION
A3: Project Name | C3: 0
A4: Project Code | C4: 0
A7: Funtion level 1 | B7: Funtion level 2 | C7: Action & Even
A8: 6.1 Login & Logout | B8: Sign in | F8: Diễn giải hành động và sự kiện của dự án đã có ví dụ diễn giải cách phân tích để lấy.
B9: Login | C9: Nhập pass
C10: Nhập user
B11: Forgot pass
B12: Logout
A14: 6.2 Organisations | B14: 6.2.1 List Organisations | C14: Hiển thị danh sách | D14: Bấm Organisation tại menu
D15: Tich nut include in-active
C16: Filter (lọc) | D16: Bấm chọn các vùng lọc
C17: Sort (sắp xếp) | D17: Bấm chọn các cột
C18: Phân trang | D18: Bấm chọn các nút dịch chuyển
C19: Chọn 1 Organisation | D19: Bấm chọn với organisation đang active và inactive
B20: 6.2.2 Add Organisation
B21: 6.2.3 Amend Organisation
B22: 6.2.4 Mark In-active Organisation
B23: 6.2.5 Supporting Materials Maintenance
B24: 6.2.6 Directorate Maintenance
B25: 6.2.7 Department Maintenance
B26: 6.2.8 Team Maintenance | C26: list team

Sheet PROTOTYPE
A3: Oranisation List
A5: Tên chức năng
H19: Hình ảnh chức năng
A25: Liệt kê các chức năng thực hiện kiểm thử theo thứ tự và kèm hình ảnh

Sheet 1. Tên Chức Năng Test
K1: Pass
A2: Module Code | K2: Fail
A3: Test requirement | K3: Untested
A4: Tester | B4: lbee3 | K4: N/A
A5: Pass | B5: Fail | C5: Untested | E5: N/A | G5: Number of Test cases | K5: =NOW() -> 45827.59
G6: =COUNTA(A11:A42) -> 29
A7: Validation Rules | B7: Tên: [10:100] Đơn vị tính: INT có value = {10000:9999999999} Đơn vị tiền: [5:9] Loại dịch vụ: Tạm thời/Vô thời hạn
A8: ID | B8: Test Title | C8: Test Case Description | D8: Test Case Procedure | E8: Test Data | F8: Expected Output | G8: Actual Result | H8: Inter-test case Dependence | I8: Result | J8: Test date | K8: Note
A9: Câu 1: 15 TC | B9: Kĩ thuật: Giá trị biên - Vùng tương đương
B10: Vùng tương đương
A11: C1_01 | H11: Administrator | I11: Pass | J11: =TODAY() -> 45827
A12: C1_02 | H12: Administrator | I12: Pass | J12: =TODAY() -> 45827
A13: C1_03 | H13: Administrator | I13: Pass | J13: =TODAY() -> 45827
A14: C1_04 | H14: Administrator | I14: Pass | J14: =TODAY() -> 45827
B15: Giá trị biên
A16: C1_05 | H16: Administrator | I16: Pass | J16: =TODAY() -> 45827
A17: C1_06 | H17: Administrator | I17: Pass | J17: =TODAY() -> 45827
A18: C1_07 | H18: Administrator | I18: Pass | J18: =TODAY() -> 45827
A19: C1_08 | H19: Administrator | I19: Pass | J19: =TODAY() -> 45827
A20: C1_09 | H20: Administrator | I20: Pass | J20: =TODAY() -> 45827
A21: C1_10 | H21: Administrator | I21: Pass | J21: =TODAY() -> 45827
A22: C1_11 | H22: Administrator | I22: Pass | J22: =TODAY() -> 45827
A23: C1_12 | H23: Administrator | I23: Pass | J23: =TODAY() -> 45827
A24: C1_13 | H24: Administrator | I24: Pass | J24: =TODAY() -> 45827
A25: C1_14 | H25: Administrator | I25: Pass | J25: =TODAY() -> 45827
A26: C1_15 | H26: Administrator | I26: Pass | J26: =TODAY() -> 45827
A27: C1_16 | H27: Administrator | I27: Pass | J27: =TODAY() -> 45827
A28: Câu 2: 5 TC | B28: Kĩ thuật: Bảng quyết định / Chuyển đổi trạng thái / Đoán lỗi
B29: Đoán lỗi
A30: C2_01 | H30: Administrator | I30: Pass | J30: =TODAY() -> 45827
A31: C2_02 | H31: Administrator | I31: Pass | J31: =TODAY() -> 45827
A32: C2_03 | H32: Administrator | I32: Pass | J32: =TODAY() -> 45827
A33: C2_04 | H33: Administrator | I33: Pass | J33: =TODAY() -> 45827
A34: C2_05 | H34: Administrator | I34: Pass | J34: =TODAY() -> 45827
A35: Câu 3: 5 TC | B35: Kĩ thuật: Kiểm thử hộp trắng
A36: C3_01
A37: C3_02
A38: C3_03
A39: C3_04
A40: C3_05
...

Sheet 2. Tên Chức Năng Test

Sheet ,,,,,

Sheet Non Function

Sheet Test Report
B1: TEST REPORT
B3: Project Name | C3: Xây dựng website đấu giá | E3: Creator | H3: Lê Chiêu Quốc, Thái Trung Đức, Phạm Như Ngọc Tuấn
B4: Project Code | C4: KH_HUE_T07 | E4: Reviewer/Approver
B5: Document Code | C5: =C4&"_"&"Test Report"&"_"&"vx.x" -> KH_HUE_T07_Test Report_vx.x | E5: Issue Date | H5: 42666
B6: Notes | C6: Release 1 includes 9 modules: 1. Đăng ký 2. Đăng nhập 3. Xem danh sách phiên đấu giá - Tìm kiếm 4. Xem chi tiết phiên đấu giá - Đấu giá/Hủy đấu giá 5. Cập nhật thông tin cá nhân - Xem lịch sử giao dịch 6. Quản lý Phiên đấu giá (Thêm - Chỉnh sửa - Xóa) 7. Quản lý Sản phẩm (Thêm - Chỉnh sửa - Xóa) 8. Quản lý Thành viên (Thêm - Chỉnh sửa) 9. Nạp/Rút tiền
B10: No | C10: Module code | D10: Pass | E10: Fail | F10: Untested | G10: N/A | H10: Number of test cases
B11: 1 | C11: ='1. Tên Chức Năng Test'!B2 -> 0 | D11: ='1. Tên Chức Năng Test'!A6 -> 0 | E11: ='1. Tên Chức Năng Test'!B6 -> 0 | F11: ='1. Tên Chức Năng Test'!C6 -> 0 | G11: ='1. Tên Chức Năng Test'!E6 -> 0 | H11: ='1. Tên Chức Năng Test'!G6 -> 29 | I11: 1.Login-logout
B12: 2 | C12: =I12&"'!B2" -> 2.organisation'!B2 | D12: 2 | E12: 1 | F12: 0 | G12: 0 | H12: 3 | I12: 2.organisation
B13: 3 | C13: =I13&"'!B2" -> 3.service'!B2 | I13: 3.service
B14: 4 | C14: =I14&"'!B2" -> 4.programe'!B2 | I14: 4.programe
B15: 5 | C15: =I15&"'!B2" -> 5. premise'!B2 | I15: 5. premise
B16: 6 | C16: =I16&"'!B2" -> 6.Geography'!B2 | I16: 6.Geography
B17: 7 | C17: =I17&"'!B2" -> 7.Search'!B2 | I17: 7.Search
B18: 8
B19: 9
C20: Sub total | D20: =SUM(D9:D19) -> 2 | E20: =SUM(E9:E19) -> 1 | F20: =SUM(F9:F19) -> 0 | G20: =SUM(G9:G19) -> 0 | H20: =SUM(H9:H19) -> 32
C22: Test coverage | E22: =(D20+E20)*100/(H20-G20) -> 9.375 | F22: %
C23: Test successful coverage | E23: =D20*100/(H20-G20) -> 6.25 | F23: %
